
#######################################################################
# +-----------------------------------------------------------------+ #
# |                            BO3 object                           | #
# +-----------------------------------------------------------------+ #
#######################################################################

Author: Unknown

Description: No description given

Version: 3

SettingsMode: WriteWithoutComments


#######################################################################
# +-----------------------------------------------------------------+ #
# |                          Main settings                          | #
# +-----------------------------------------------------------------+ #
#######################################################################

Tree: true

Frequency: 0

Rarity: 100.0

MaxSpawn: 0

RotateRandomly: false

SpawnHeight: highestBlock

SpawnHeightOffset: 0

SpawnHeightVariance: 0

##############################
# Height Limits for the BO3. #
##############################

MinHeight: 0

MaxHeight: 256

######################
# Extrusion settings #
######################

ExtrudeMode: None

ExtrudeThroughBlocks: minecraft:air

MaxBranchDepth: 10


#######################################################################
# +-----------------------------------------------------------------+ #
# |                      Source block settings                      | #
# +-----------------------------------------------------------------+ #
#######################################################################

SourceBlocks: minecraft:air

MaxPercentageOutsideSourceBlock: 100

OutsideSourceBlock: placeAnyway

DoReplaceBlocks: true

IsOTGPlus: false


#######################################################################
# +-----------------------------------------------------------------+ #
# |                              Blocks                             | #
# +-----------------------------------------------------------------+ #
#######################################################################

B(-7,0,-7,minecraft:grass_block)
B(-7,0,-6,minecraft:grass_block)
B(-7,0,-5,minecraft:grass_block)
B(-7,0,-4,minecraft:grass_block)
B(-7,0,-3,minecraft:dirt)
B(-7,1,-3,minecraft:grass_block)
B(-7,0,-2,minecraft:dirt)
B(-7,1,-2,minecraft:grass_block)
B(-7,0,-1,minecraft:dirt)
B(-7,1,-1,minecraft:grass_block)
B(-7,2,-1,minecraft:grass)
B(-7,0,0,minecraft:dirt)
B(-7,1,0,minecraft:grass_block)
B(-7,0,1,minecraft:dirt)
B(-7,1,1,minecraft:grass_block)
B(-7,0,2,minecraft:dirt)
B(-7,1,2,minecraft:dirt)
B(-7,2,2,immersiveengineering:sheetmetal_steel)
B(-7,3,2,immersiveengineering:sheetmetal_steel)
B(-7,4,2,immersiveengineering:sheetmetal_steel)
B(-7,5,2,immersiveengineering:slab_sheetmetal_steel)
B(-7,0,3,minecraft:dirt)
B(-7,1,3,minecraft:grass_block)
B(-7,0,4,minecraft:dirt)
B(-7,1,4,minecraft:grass_block)
B(-7,0,5,minecraft:dirt)
B(-7,1,5,minecraft:grass_block)
B(-7,2,5,minecraft:oxeye_daisy)
B(-7,0,6,minecraft:dirt)
B(-7,1,6,factoriores:gangue)
B(-7,0,7,minecraft:dirt)
B(-7,1,7,minecraft:grass_block)
B(-7,2,7,minecraft:grass)
B(-6,0,-7,minecraft:grass_block)
B(-6,0,-6,minecraft:grass_block)
B(-6,0,-5,minecraft:grass_block)
B(-6,0,-4,minecraft:dirt)
B(-6,1,-4,minecraft:grass_block)
B(-6,0,-3,minecraft:dirt)
B(-6,1,-3,minecraft:grass_block)
B(-6,0,-2,minecraft:dirt)
B(-6,1,-2,minecraft:grass_block)
B(-6,0,-1,minecraft:dirt)
B(-6,1,-1,minecraft:grass_block)
B(-6,0,0,minecraft:dirt)
B(-6,1,0,minecraft:grass_block)
B(-6,0,1,minecraft:dirt)
B(-6,1,1,minecraft:grass_block)
B(-6,0,2,minecraft:dirt)
B(-6,1,2,minecraft:grass_block)
B(-6,3,2,immersiveengineering:connector_lv_relay[facing=west,waterlogged=false],spawnarea1/immersiveengineering_lv_relay_-6_3_2.nbt)
B(-6,4,2,immersiveengineering:connector_lv[facing=up,waterlogged=false],spawnarea1/immersiveengineering_lv_conn_-6_4_2.nbt)
B(-6,5,2,mekanismgenerators:solar_generator[active=false,facing=east,waterlogged=0],spawnarea1/mekanismgenerators_solar_generator_-6_5_2.nbt)
B(-6,0,3,minecraft:dirt)
B(-6,1,3,minecraft:grass_block)
B(-6,2,3,minecraft:oxeye_daisy)
B(-6,0,4,minecraft:dirt)
B(-6,1,4,factoriores:gangue)
B(-6,0,5,minecraft:dirt)
B(-6,1,5,factoriores:iron_ore,spawnarea1/factoriores_ore_deposit_tile_-6_1_5.nbt)
B(-6,0,6,factoriores:coal_ore,spawnarea1/factoriores_ore_deposit_tile_-6_0_6.nbt)
B(-6,1,6,factoriores:coal_ore,spawnarea1/factoriores_ore_deposit_tile_-6_1_6.nbt)
B(-6,0,7,factoriores:coal_ore,spawnarea1/factoriores_ore_deposit_tile_-6_0_7.nbt)
B(-6,1,7,factoriores:coal_ore,spawnarea1/factoriores_ore_deposit_tile_-6_1_7.nbt)
B(-6,0,8,minecraft:dirt)
B(-6,1,8,minecraft:grass_block)
B(-6,2,8,minecraft:grass)
B(-5,0,-7,minecraft:grass_block)
B(-5,0,-6,minecraft:grass_block)
B(-5,0,-5,minecraft:grass_block)
B(-5,0,-4,minecraft:dirt)
B(-5,1,-4,minecraft:grass_block)
B(-5,0,-3,minecraft:dirt)
B(-5,1,-3,minecraft:grass_block)
B(-5,0,-2,minecraft:dirt)
B(-5,1,-2,minecraft:grass_block)
B(-5,0,-1,minecraft:dirt)
B(-5,1,-1,minecraft:grass_block)
B(-5,2,-1,immersiveposts:postbase,spawnarea1/immersiveposts_postbase_-5_2_-1.nbt)
B(-5,3,-1,immersiveposts:steelpost[facing=north,flipstate=up,parm_east=false,parm_north=false,parm_south=false,parm_west=false,type=post,waterlogged=false])
B(-5,4,-1,immersiveposts:steelpost)
B(-5,5,-1,immersiveengineering:electric_lantern[active=true,facing=down,waterlogged=false],spawnarea1/immersiveengineering_electriclantern_-5_5_-1.nbt)
B(-5,0,0,minecraft:dirt)
B(-5,1,0,minecraft:grass_block)
B(-5,2,0,create:schematic_table[facing=east],spawnarea1/create_schematic_table_-5_2_0.nbt)
B(-5,0,1,minecraft:dirt)
B(-5,1,1,minecraft:grass_block)
B(-5,0,2,minecraft:dirt)
B(-5,1,2,minecraft:grass_block)
B(-5,0,3,minecraft:dirt)
B(-5,1,3,factoriores:gangue)
B(-5,0,4,factoriores:copper_ore,spawnarea1/factoriores_ore_deposit_tile_-5_0_4.nbt)
B(-5,1,4,factoriores:copper_ore,spawnarea1/factoriores_ore_deposit_tile_-5_1_4.nbt)
B(-5,3,4,immersiveengineering:connector_lv[facing=south,waterlogged=false],spawnarea1/immersiveengineering_lv_conn_-5_3_4.nbt)
B(-5,0,5,minecraft:dirt)
B(-5,1,5,factoriores:copper_ore,spawnarea1/factoriores_ore_deposit_tile_-5_1_5.nbt)
B(-5,3,5,factoriores:electrical_miner[enabled=false,lit=3],spawnarea1/factoriores_electrical_miner_tile_-5_3_5.nbt)
B(-5,0,6,minecraft:dirt)
B(-5,1,6,factoriores:iron_ore,spawnarea1/factoriores_ore_deposit_tile_-5_1_6.nbt)
B(-5,0,7,factoriores:coal_ore,spawnarea1/factoriores_ore_deposit_tile_-5_0_7.nbt)
B(-5,1,7,factoriores:coal_ore,spawnarea1/factoriores_ore_deposit_tile_-5_1_7.nbt)
B(-5,0,8,minecraft:dirt)
B(-5,1,8,minecraft:grass_block)
B(-4,0,-7,minecraft:grass_block)
B(-4,0,-6,minecraft:dirt)
B(-4,1,-6,minecraft:grass_block)
B(-4,0,-5,minecraft:dirt)
B(-4,1,-5,minecraft:grass_block)
B(-4,2,-5,immersiveengineering:turret_gun[facing=west,multiblockslave=false],spawnarea1/immersiveengineering_turretgun_-4_2_-5.nbt)
B(-4,3,-5,immersiveengineering:turret_gun[facing=west,multiblockslave=true],spawnarea1/immersiveengineering_turretgun_-4_3_-5.nbt)
B(-4,0,-4,minecraft:dirt)
B(-4,1,-4,minecraft:grass_block)
B(-4,2,-4,immersiveengineering:connector_lv,spawnarea1/immersiveengineering_lv_conn_-4_2_-4.nbt)
B(-4,0,-3,minecraft:dirt)
B(-4,1,-3,minecraft:grass_block)
B(-4,0,-2,minecraft:dirt)
B(-4,1,-2,minecraft:grass_block)
B(-4,0,-1,minecraft:dirt)
B(-4,1,-1,minecraft:grass_block)
B(-4,0,0,minecraft:dirt)
B(-4,1,0,minecraft:grass_block)
B(-4,0,1,minecraft:dirt)
B(-4,1,1,minecraft:grass_block)
B(-4,0,2,minecraft:dirt)
B(-4,1,2,minecraft:grass_block)
B(-4,0,3,minecraft:dirt)
B(-4,1,3,minecraft:grass_block)
B(-4,2,3,minecraft:grass)
B(-4,0,4,minecraft:dirt)
B(-4,1,4,factoriores:gangue)
B(-4,0,5,minecraft:dirt)
B(-4,1,5,factoriores:copper_ore,spawnarea1/factoriores_ore_deposit_tile_-4_1_5.nbt)
B(-4,0,6,factoriores:iron_ore,spawnarea1/factoriores_ore_deposit_tile_-4_0_6.nbt)
B(-4,1,6,factoriores:iron_ore,spawnarea1/factoriores_ore_deposit_tile_-4_1_6.nbt)
B(-4,0,7,minecraft:dirt)
B(-4,1,7,factoriores:iron_ore,spawnarea1/factoriores_ore_deposit_tile_-4_1_7.nbt)
B(-4,0,8,minecraft:dirt)
B(-4,1,8,minecraft:grass_block)
B(-3,0,-7,minecraft:dirt)
B(-3,1,-7,minecraft:grass_block)
B(-3,0,-6,minecraft:dirt)
B(-3,1,-6,minecraft:grass_block)
B(-3,0,-5,minecraft:dirt)
B(-3,1,-5,minecraft:grass_block)
B(-3,0,-4,minecraft:dirt)
B(-3,1,-4,minecraft:grass_block)
B(-3,0,-3,minecraft:dirt)
B(-3,1,-3,minecraft:dirt)
B(-3,2,-3,minecraft:grass_block)
B(-3,0,-2,minecraft:dirt)
B(-3,1,-2,minecraft:dirt)
B(-3,2,-2,minecraft:grass_block)
B(-3,0,-1,minecraft:dirt)
B(-3,1,-1,minecraft:dirt)
B(-3,2,-1,minecraft:grass_block)
B(-3,0,0,minecraft:dirt)
B(-3,1,0,minecraft:dirt)
B(-3,2,0,minecraft:grass_block)
B(-3,0,1,minecraft:dirt)
B(-3,1,1,minecraft:dirt)
B(-3,2,1,minecraft:grass_block)
B(-3,0,2,minecraft:dirt)
B(-3,1,2,minecraft:dirt)
B(-3,2,2,minecraft:grass_block)
B(-3,3,2,minecraft:lily_of_the_valley)
B(-3,0,3,minecraft:dirt)
B(-3,1,3,minecraft:grass_block)
B(-3,0,4,minecraft:dirt)
B(-3,1,4,minecraft:grass_block)
B(-3,0,5,minecraft:dirt)
B(-3,1,5,minecraft:grass_block)
B(-3,2,5,krate:krate_small[facing=north,waterlogged=false],spawnarea1/krate_krate_small_-3_2_5.nbt)
B(-3,0,6,minecraft:dirt)
B(-3,1,6,factoriores:gangue)
B(-3,0,7,minecraft:dirt)
B(-3,1,7,minecraft:grass_block)
B(-3,0,8,minecraft:dirt)
B(-3,1,8,minecraft:grass_block)
B(-2,0,-7,minecraft:dirt)
B(-2,1,-7,minecraft:grass_block)
B(-2,0,-6,minecraft:dirt)
B(-2,1,-6,minecraft:grass_block)
B(-2,0,-5,minecraft:dirt)
B(-2,1,-5,minecraft:grass_block)
B(-2,0,-4,minecraft:dirt)
B(-2,1,-4,minecraft:grass_block)
B(-2,0,-3,minecraft:dirt)
B(-2,1,-3,minecraft:dirt)
B(-2,2,-3,minecraft:grass_block)
B(-2,0,-2,minecraft:dirt)
B(-2,1,-2,minecraft:dirt)
B(-2,2,-2,minecraft:grass_block)
B(-2,3,-2,extendedcrafting:ultimate_auto_table,spawnarea1/extendedcrafting_ultimate_auto_table_-2_3_-2.nbt)
B(-2,0,-1,minecraft:dirt)
B(-2,1,-1,minecraft:dirt)
B(-2,2,-1,minecraft:grass_block)
B(-2,3,-1,mekanism:creative_energy_cube[facing=up,waterlogged=0],spawnarea1/mekanism_creative_energy_cube_-2_3_-1.nbt)
B(-2,0,0,minecraft:dirt)
B(-2,1,0,minecraft:dirt)
B(-2,2,0,minecraft:grass_block)
B(-2,0,1,minecraft:dirt)
B(-2,1,1,minecraft:dirt)
B(-2,2,1,minecraft:grass_block)
B(-2,0,2,minecraft:dirt)
B(-2,1,2,minecraft:dirt)
B(-2,2,2,minecraft:grass_block)
B(-2,0,3,minecraft:dirt)
B(-2,1,3,minecraft:grass_block)
B(-2,0,4,minecraft:dirt)
B(-2,1,4,minecraft:grass_block)
B(-2,0,5,minecraft:dirt)
B(-2,1,5,minecraft:grass_block)
B(-2,2,5,krate:krate_large[facing=north,waterlogged=false],spawnarea1/krate_krate_large_-2_2_5.nbt)
B(-2,0,6,minecraft:dirt)
B(-2,1,6,minecraft:grass_block)
B(-2,0,7,minecraft:dirt)
B(-2,1,7,minecraft:grass_block)
B(-2,2,7,minecraft:grass)
B(-2,0,8,minecraft:dirt)
B(-2,1,8,minecraft:grass_block)
B(-1,0,-7,minecraft:dirt)
B(-1,1,-7,minecraft:grass_block)
B(-1,0,-6,minecraft:dirt)
B(-1,1,-6,minecraft:dirt)
B(-1,0,-5,minecraft:dirt)
B(-1,1,-5,minecraft:grass_block)
B(-1,0,-4,minecraft:dirt)
B(-1,1,-4,minecraft:grass_block)
B(-1,0,-3,minecraft:dirt)
B(-1,1,-3,minecraft:dirt)
B(-1,2,-3,minecraft:grass_block)
B(-1,0,-2,minecraft:dirt)
B(-1,1,-2,minecraft:dirt)
B(-1,2,-2,minecraft:grass_block)
B(-1,3,-2,extendedcrafting:elite_auto_table,spawnarea1/extendedcrafting_elite_auto_table_-1_3_-2.nbt)
B(-1,0,-1,minecraft:dirt)
B(-1,1,-1,minecraft:dirt)
B(-1,2,-1,minecraft:grass_block)
B(-1,3,-1,mekanism:creative_energy_cube[facing=up,waterlogged=0],spawnarea1/mekanism_creative_energy_cube_-1_3_-1.nbt)
B(-1,0,0,minecraft:dirt)
B(-1,1,0,minecraft:dirt)
B(-1,2,0,minecraft:grass_block)
B(-1,3,0,createaddition:rolling_mill[facing=west],spawnarea1/createaddition_rolling_mill_-1_3_0.nbt)
B(-1,0,1,minecraft:dirt)
B(-1,1,1,minecraft:dirt)
B(-1,2,1,minecraft:grass_block)
B(-1,0,2,minecraft:dirt)
B(-1,1,2,minecraft:dirt)
B(-1,2,2,immersiveengineering:sheetmetal_copper)
B(-1,0,3,minecraft:dirt)
B(-1,1,3,minecraft:grass_block)
B(-1,0,4,minecraft:dirt)
B(-1,1,4,minecraft:grass_block)
B(-1,0,5,minecraft:dirt)
B(-1,1,5,minecraft:grass_block)
B(-1,2,5,krate:krate_big[facing=north,waterlogged=false],spawnarea1/krate_krate_big_-1_2_5.nbt)
B(-1,0,6,minecraft:dirt)
B(-1,1,6,minecraft:dirt)
B(-1,2,6,minecraft:crafting_table)
B(-1,0,7,minecraft:dirt)
B(-1,1,7,minecraft:grass_block)
B(-1,2,7,krate:krate_big[facing=north,waterlogged=false],spawnarea1/krate_krate_big_-1_2_7.nbt)
B(-1,0,8,minecraft:dirt)
B(-1,1,8,minecraft:dirt)
B(0,0,-7,minecraft:dirt)
B(0,1,-7,minecraft:grass_block)
B(0,0,-6,minecraft:dirt)
B(0,1,-6,minecraft:dirt)
B(0,0,-5,minecraft:dirt)
B(0,1,-5,minecraft:grass_block)
B(0,0,-4,minecraft:dirt)
B(0,1,-4,minecraft:grass_block)
B(0,0,-3,minecraft:dirt)
B(0,1,-3,minecraft:dirt)
B(0,2,-3,minecraft:grass_block)
B(0,0,-2,minecraft:dirt)
B(0,1,-2,minecraft:dirt)
B(0,2,-2,minecraft:grass_block)
B(0,3,-2,extendedcrafting:advanced_auto_table,spawnarea1/extendedcrafting_advanced_auto_table_0_3_-2.nbt)
B(0,0,-1,minecraft:dirt)
B(0,1,-1,minecraft:dirt)
B(0,2,-1,minecraft:grass_block)
B(0,3,-1,mekanism:creative_energy_cube,spawnarea1/mekanism_creative_energy_cube_0_3_-1.nbt)
B(0,0,0,minecraft:dirt)
B(0,1,0,minecraft:dirt)
B(0,2,0,minecraft:grass_block)
B(0,0,1,minecraft:dirt)
B(0,1,1,minecraft:dirt)
B(0,2,1,minecraft:grass_block)
B(0,0,2,minecraft:dirt)
B(0,1,2,minecraft:dirt)
B(0,2,2,immersiveengineering:sheetmetal_copper)
B(0,0,3,minecraft:dirt)
B(0,1,3,minecraft:grass_block)
B(0,0,4,minecraft:dirt)
B(0,1,4,minecraft:grass_block)
B(0,0,5,minecraft:dirt)
B(0,1,5,minecraft:grass_block)
B(0,0,6,minecraft:dirt)
B(0,1,6,minecraft:grass_block)
B(0,0,7,minecraft:dirt)
B(0,1,7,minecraft:grass_block)
B(0,0,8,minecraft:dirt)
B(0,1,8,minecraft:grass_block)
B(1,0,-7,minecraft:dirt)
B(1,1,-7,minecraft:grass_block)
B(1,0,-6,minecraft:dirt)
B(1,1,-6,minecraft:grass_block)
B(1,0,-5,minecraft:dirt)
B(1,1,-5,minecraft:grass_block)
B(1,0,-4,minecraft:dirt)
B(1,1,-4,minecraft:grass_block)
B(1,0,-3,minecraft:dirt)
B(1,1,-3,minecraft:dirt)
B(1,2,-3,minecraft:grass_block)
B(1,0,-2,minecraft:dirt)
B(1,1,-2,minecraft:dirt)
B(1,2,-2,minecraft:grass_block)
B(1,3,-2,extendedcrafting:basic_auto_table,spawnarea1/extendedcrafting_basic_auto_table_1_3_-2.nbt)
B(1,0,-1,minecraft:dirt)
B(1,1,-1,minecraft:dirt)
B(1,2,-1,minecraft:grass_block)
B(1,3,-1,mekanism:creative_energy_cube[facing=west,waterlogged=0],spawnarea1/mekanism_creative_energy_cube_1_3_-1.nbt)
B(1,0,0,minecraft:dirt)
B(1,1,0,minecraft:dirt)
B(1,2,0,minecraft:grass_block)
B(1,0,1,minecraft:dirt)
B(1,1,1,minecraft:dirt)
B(1,2,1,minecraft:grass_block)
B(1,3,1,mekanism:chemical_crystallizer[active=false,facing=west,waterlogged=0],spawnarea1/mekanism_chemical_crystallizer_1_3_1.nbt)
B(1,0,2,minecraft:dirt)
B(1,1,2,minecraft:dirt)
B(1,2,2,immersiveengineering:sheetmetal_copper)
B(1,0,3,minecraft:dirt)
B(1,1,3,minecraft:grass_block)
B(1,0,4,minecraft:dirt)
B(1,1,4,minecraft:grass_block)
B(1,0,5,minecraft:dirt)
B(1,1,5,minecraft:dirt)
B(1,0,6,minecraft:dirt)
B(1,1,6,minecraft:grass_block)
B(1,0,7,minecraft:dirt)
B(1,1,7,minecraft:grass_block)
B(1,0,8,minecraft:dirt)
B(1,1,8,minecraft:grass_block)
B(2,0,-7,minecraft:dirt)
B(2,1,-7,minecraft:grass_block)
B(2,0,-6,minecraft:dirt)
B(2,1,-6,minecraft:grass_block)
B(2,0,-5,minecraft:dirt)
B(2,1,-5,minecraft:grass_block)
B(2,2,-5,minecraft:grass)
B(2,0,-4,minecraft:dirt)
B(2,1,-4,minecraft:grass_block)
B(2,0,-3,minecraft:dirt)
B(2,1,-3,minecraft:dirt)
B(2,2,-3,minecraft:grass_block)
B(2,0,-2,minecraft:dirt)
B(2,1,-2,minecraft:dirt)
B(2,2,-2,minecraft:grass_block)
B(2,3,-2,minecraft:tall_grass)
B(2,4,-2,minecraft:tall_grass[half=upper])
B(2,0,-1,minecraft:dirt)
B(2,1,-1,minecraft:dirt)
B(2,2,-1,minecraft:grass_block)
B(2,0,0,minecraft:dirt)
B(2,1,0,minecraft:dirt)
B(2,2,0,minecraft:grass_block)
B(2,0,1,minecraft:dirt)
B(2,1,1,minecraft:dirt)
B(2,2,1,immersiveengineering:sheetmetal_steel)
B(2,3,1,mekanism:creative_chemical_tank[facing=west,waterlogged=0],spawnarea1/mekanism_creative_chemical_tank_2_3_1.nbt)
B(2,0,2,minecraft:dirt)
B(2,1,2,minecraft:dirt)
B(2,2,2,immersiveengineering:sheetmetal_copper)
B(2,0,3,minecraft:dirt)
B(2,1,3,minecraft:grass_block)
B(2,0,4,minecraft:dirt)
B(2,1,4,minecraft:grass_block)
B(2,0,5,minecraft:dirt)
B(2,1,5,minecraft:dirt)
B(2,0,6,minecraft:dirt)
B(2,1,6,minecraft:dirt)
B(2,0,7,minecraft:dirt)
B(2,1,7,minecraft:dirt)
B(2,0,8,minecraft:dirt)
B(2,1,8,minecraft:grass_block)
B(3,0,-7,minecraft:dirt)
B(3,1,-7,minecraft:grass_block)
B(3,0,-6,minecraft:dirt)
B(3,1,-6,minecraft:grass_block)
B(3,0,-5,minecraft:dirt)
B(3,1,-5,minecraft:grass_block)
B(3,2,-5,minecraft:grass)
B(3,0,-4,minecraft:dirt)
B(3,1,-4,minecraft:grass_block)
B(3,0,-3,minecraft:dirt)
B(3,1,-3,minecraft:dirt)
B(3,2,-3,immersiveengineering:sheetmetal_steel)
B(3,0,-2,minecraft:dirt)
B(3,1,-2,minecraft:dirt)
B(3,2,-2,immersiveengineering:sheetmetal_steel)
B(3,0,-1,minecraft:dirt)
B(3,1,-1,minecraft:dirt)
B(3,2,-1,immersiveengineering:sheetmetal_steel)
B(3,0,0,minecraft:dirt)
B(3,1,0,minecraft:dirt)
B(3,2,0,immersiveengineering:sheetmetal_steel)
B(3,0,1,minecraft:dirt)
B(3,1,1,minecraft:dirt)
B(3,2,1,immersiveengineering:sheetmetal_steel)
B(3,0,2,minecraft:dirt)
B(3,1,2,minecraft:grass_block)
B(3,0,3,minecraft:dirt)
B(3,1,3,minecraft:dirt)
B(3,0,4,minecraft:dirt)
B(3,1,4,minecraft:grass_block)
B(3,0,5,minecraft:dirt)
B(3,1,5,minecraft:grass_block)
B(3,2,5,mekanism:creative_energy_cube,spawnarea1/mekanism_creative_energy_cube_3_2_5.nbt)
B(3,3,5,immersiveengineering:charging_station,spawnarea1/immersiveengineering_chargingstation_3_3_5.nbt)
B(3,0,6,minecraft:dirt)
B(3,1,6,minecraft:grass_block)
B(3,0,7,minecraft:dirt)
B(3,1,7,minecraft:grass_block)
B(3,0,8,minecraft:dirt)
B(3,1,8,minecraft:grass_block)
B(4,0,-7,minecraft:dirt)
B(4,1,-7,minecraft:grass_block)
B(4,2,-7,minecraft:red_tulip)
B(4,0,-6,minecraft:dirt)
B(4,1,-6,minecraft:grass_block)
B(4,2,-6,minecraft:grass)
B(4,0,-5,minecraft:dirt)
B(4,1,-5,minecraft:grass_block)
B(4,2,-5,minecraft:grass)
B(4,0,-4,minecraft:dirt)
B(4,1,-4,minecraft:grass_block)
B(4,0,-3,minecraft:dirt)
B(4,1,-3,minecraft:grass_block)
B(4,6,-3,minecraft:birch_leaves[distance=4,persistent=false])
B(4,0,-2,minecraft:dirt)
B(4,1,-2,minecraft:grass_block)
B(4,2,-2,minecraft:grass)
B(4,6,-2,minecraft:birch_leaves[distance=3,persistent=false])
B(4,7,-2,minecraft:birch_leaves[distance=3,persistent=false])
B(4,0,-1,minecraft:dirt)
B(4,1,-1,minecraft:grass_block)
B(4,6,-1,minecraft:birch_leaves[distance=2,persistent=false])
B(4,7,-1,minecraft:birch_leaves[distance=2,persistent=false])
B(4,0,0,minecraft:dirt)
B(4,1,0,minecraft:grass_block)
B(4,6,0,minecraft:birch_leaves[distance=3,persistent=false])
B(4,7,0,minecraft:birch_leaves[distance=3,persistent=false])
B(4,0,1,minecraft:dirt)
B(4,1,1,minecraft:grass_block)
B(4,7,1,minecraft:birch_leaves[distance=4,persistent=false])
B(4,0,2,minecraft:dirt)
B(4,1,2,minecraft:grass_block)
B(4,0,3,minecraft:dirt)
B(4,1,3,minecraft:dirt)
B(4,0,4,minecraft:dirt)
B(4,1,4,minecraft:grass_block)
B(4,0,5,minecraft:dirt)
B(4,1,5,minecraft:dirt)
B(4,2,5,extendedcrafting:compressor,spawnarea1/extendedcrafting_compressor_4_2_5.nbt)
B(4,0,6,minecraft:dirt)
B(4,1,6,minecraft:grass_block)
B(4,2,6,minecraft:grass)
B(4,0,7,minecraft:dirt)
B(4,1,7,minecraft:grass_block)
B(4,0,8,minecraft:dirt)
B(4,1,8,minecraft:grass_block)
B(5,0,-7,minecraft:dirt)
B(5,1,-7,minecraft:grass_block)
B(5,0,-6,minecraft:dirt)
B(5,1,-6,minecraft:grass_block)
B(5,0,-5,minecraft:dirt)
B(5,1,-5,immersiveengineering:sheetmetal_steel)
B(5,0,-4,minecraft:dirt)
B(5,1,-4,minecraft:grass_block)
B(5,0,-3,minecraft:dirt)
B(5,1,-3,minecraft:grass_block)
B(5,6,-3,minecraft:birch_leaves[distance=3,persistent=false])
B(5,7,-3,minecraft:birch_leaves[distance=3,persistent=false])
B(5,0,-2,minecraft:dirt)
B(5,1,-2,minecraft:grass_block)
B(5,6,-2,minecraft:birch_leaves[distance=2,persistent=false])
B(5,7,-2,minecraft:birch_leaves[distance=2,persistent=false])
B(5,8,-2,minecraft:birch_leaves[distance=2,persistent=false])
B(5,0,-1,minecraft:dirt)
B(5,1,-1,minecraft:grass_block)
B(5,2,-1,minecraft:grass)
B(5,6,-1,minecraft:birch_leaves)
B(5,7,-1,minecraft:birch_leaves)
B(5,8,-1,minecraft:birch_leaves)
B(5,9,-1,minecraft:birch_leaves[distance=2,persistent=false])
B(5,0,0,minecraft:dirt)
B(5,1,0,minecraft:grass_block)
B(5,2,0,minecraft:grass)
B(5,6,0,minecraft:birch_leaves[distance=2,persistent=false])
B(5,7,0,minecraft:birch_leaves[distance=2,persistent=false])
B(5,8,0,minecraft:birch_leaves[distance=2,persistent=false])
B(5,0,1,minecraft:dirt)
B(5,1,1,minecraft:grass_block)
B(5,6,1,minecraft:birch_leaves[distance=3,persistent=false])
B(5,7,1,minecraft:birch_leaves[distance=3,persistent=false])
B(5,0,2,minecraft:dirt)
B(5,1,2,minecraft:grass_block)
B(5,0,3,minecraft:dirt)
B(5,1,3,minecraft:grass_block)
B(5,0,4,minecraft:dirt)
B(5,1,4,minecraft:grass_block)
B(5,0,5,minecraft:dirt)
B(5,1,5,minecraft:grass_block)
B(5,0,6,minecraft:dirt)
B(5,1,6,minecraft:grass_block)
B(5,2,6,minecraft:grass)
B(5,0,7,minecraft:dirt)
B(5,1,7,minecraft:grass_block)
B(5,0,8,minecraft:dirt)
B(5,1,8,minecraft:grass_block)
B(6,0,-7,minecraft:dirt)
B(6,1,-7,minecraft:grass_block)
B(6,0,-6,minecraft:dirt)
B(6,1,-6,immersiveengineering:sheetmetal_steel)
B(6,2,-6,mekanism:radioactive_waste_barrel[active=false,facing=south,waterlogged=0],spawnarea1/mekanism_radioactive_waste_barrel_6_2_-6.nbt)
B(6,0,-5,minecraft:dirt)
B(6,1,-5,immersiveengineering:sheetmetal_steel)
B(6,0,-4,minecraft:dirt)
B(6,1,-4,immersiveengineering:sheetmetal_steel)
B(6,0,-3,minecraft:dirt)
B(6,1,-3,minecraft:grass_block)
B(6,2,-3,minecraft:grass)
B(6,6,-3,minecraft:birch_leaves[distance=4,persistent=false])
B(6,7,-3,minecraft:birch_leaves[distance=4,persistent=false])
B(6,0,-2,minecraft:dirt)
B(6,1,-2,minecraft:grass_block)
B(6,8,-2,minecraft:birch_leaves)
B(6,9,-2,minecraft:birch_leaves[distance=2,persistent=false])
B(6,0,-1,minecraft:dirt)
B(6,1,-1,minecraft:dirt)
B(6,2,-1,minecraft:birch_log)
B(6,3,-1,minecraft:birch_log)
B(6,4,-1,minecraft:birch_log)
B(6,5,-1,minecraft:birch_log)
B(6,6,-1,minecraft:birch_log)
B(6,7,-1,minecraft:birch_log)
B(6,8,-1,minecraft:birch_log)
B(6,9,-1,minecraft:birch_leaves)
B(6,0,0,minecraft:dirt)
B(6,1,0,minecraft:grass_block)
B(6,2,0,create:mechanical_saw[axis_along_first=false,facing=north],spawnarea1/create_saw_6_2_0.nbt)
B(6,6,0,minecraft:birch_leaves)
B(6,7,0,minecraft:birch_leaves)
B(6,8,0,minecraft:birch_leaves)
B(6,9,0,minecraft:birch_leaves[distance=2,persistent=false])
B(6,0,1,minecraft:dirt)
B(6,1,1,minecraft:grass_block)
B(6,2,1,create:hand_crank[facing=south],spawnarea1/create_hand_crank_6_2_1.nbt)
B(6,6,1,minecraft:birch_leaves[distance=2,persistent=false])
B(6,7,1,minecraft:birch_leaves[distance=2,persistent=false])
B(6,0,2,minecraft:dirt)
B(6,1,2,minecraft:grass_block)
B(6,2,2,minecraft:grass)
B(6,0,3,minecraft:dirt)
B(6,1,3,minecraft:grass_block)
B(6,0,4,minecraft:dirt)
B(6,1,4,minecraft:grass_block)
B(6,2,4,minecraft:grass)
B(6,0,5,minecraft:dirt)
B(6,1,5,minecraft:grass_block)
B(6,0,6,minecraft:dirt)
B(6,1,6,minecraft:grass_block)
B(6,0,7,minecraft:dirt)
B(6,1,7,minecraft:grass_block)
B(6,0,8,minecraft:dirt)
B(6,1,8,minecraft:grass_block)
B(7,0,-7,minecraft:dirt)
B(7,1,-7,minecraft:grass_block)
B(7,0,-6,minecraft:dirt)
B(7,1,-6,minecraft:grass_block)
B(7,2,-6,mekanism:radioactive_waste_barrel[active=false,facing=south,waterlogged=0],spawnarea1/mekanism_radioactive_waste_barrel_7_2_-6.nbt)
B(7,0,-5,minecraft:dirt)
B(7,1,-5,immersiveengineering:sheetmetal_steel)
B(7,0,-4,minecraft:dirt)
B(7,1,-4,minecraft:grass_block)
B(7,0,-3,minecraft:dirt)
B(7,1,-3,minecraft:grass_block)
B(7,2,-3,minecraft:red_tulip)
B(7,6,-3,minecraft:birch_leaves[distance=3,persistent=false])
B(7,7,-3,minecraft:birch_leaves[distance=3,persistent=false])
B(7,0,-2,minecraft:dirt)
B(7,1,-2,minecraft:grass_block)
B(7,2,-2,minecraft:grass)
B(7,6,-2,minecraft:birch_leaves[distance=2,persistent=false])
B(7,7,-2,minecraft:birch_leaves[distance=2,persistent=false])
B(7,8,-2,minecraft:birch_leaves[distance=2,persistent=false])
B(7,0,-1,minecraft:dirt)
B(7,1,-1,minecraft:grass_block)
B(7,6,-1,minecraft:birch_leaves)
B(7,7,-1,minecraft:birch_leaves)
B(7,8,-1,minecraft:birch_leaves)
B(7,9,-1,minecraft:birch_leaves[distance=2,persistent=false])
B(7,0,0,minecraft:dirt)
B(7,1,0,minecraft:grass_block)
B(7,6,0,minecraft:birch_leaves[distance=2,persistent=false])
B(7,7,0,minecraft:birch_leaves[distance=2,persistent=false])
B(7,0,1,minecraft:dirt)
B(7,1,1,minecraft:grass_block)
B(7,6,1,minecraft:birch_leaves[distance=3,persistent=false])
B(7,7,1,minecraft:birch_leaves[distance=3,persistent=false])
B(7,0,2,minecraft:dirt)
B(7,1,2,minecraft:grass_block)
B(7,0,3,minecraft:dirt)
B(7,1,3,minecraft:grass_block)
B(7,0,4,minecraft:dirt)
B(7,1,4,minecraft:grass_block)
B(7,2,4,minecraft:cornflower)
B(7,0,5,minecraft:dirt)
B(7,1,5,minecraft:grass_block)
B(7,0,6,minecraft:dirt)
B(7,1,6,minecraft:grass_block)
B(7,2,6,minecraft:grass)
B(7,0,7,minecraft:grass_block)
B(7,1,7,minecraft:grass)
B(7,0,8,minecraft:water)
B(8,0,-7,minecraft:dirt)
B(8,1,-7,minecraft:grass_block)
B(8,0,-6,minecraft:dirt)
B(8,1,-6,minecraft:grass_block)
B(8,0,-5,minecraft:dirt)
B(8,1,-5,minecraft:grass_block)
B(8,0,-4,minecraft:dirt)
B(8,1,-4,minecraft:grass_block)
B(8,0,-3,minecraft:dirt)
B(8,1,-3,minecraft:grass_block)
B(8,6,-3,minecraft:birch_leaves[distance=4,persistent=false])
B(8,0,-2,minecraft:dirt)
B(8,1,-2,minecraft:grass_block)
B(8,2,-2,minecraft:red_tulip)
B(8,6,-2,minecraft:birch_leaves[distance=3,persistent=false])
B(8,7,-2,minecraft:birch_leaves[distance=3,persistent=false])
B(8,0,-1,minecraft:dirt)
B(8,1,-1,minecraft:grass_block)
B(8,2,-1,minecraft:grass)
B(8,6,-1,minecraft:birch_leaves[distance=2,persistent=false])
B(8,7,-1,minecraft:birch_leaves[distance=2,persistent=false])
B(8,0,0,minecraft:dirt)
B(8,1,0,minecraft:grass_block)
B(8,6,0,minecraft:birch_leaves[distance=3,persistent=false])
B(8,7,0,minecraft:birch_leaves[distance=3,persistent=false])
B(8,0,1,minecraft:dirt)
B(8,1,1,minecraft:grass_block)
B(8,2,1,minecraft:grass)
B(8,0,2,minecraft:dirt)
B(8,1,2,minecraft:grass_block)
B(8,2,2,minecraft:grass)
B(8,0,3,minecraft:dirt)
B(8,1,3,minecraft:grass_block)
B(8,0,4,minecraft:dirt)
B(8,1,4,minecraft:grass_block)
B(8,2,4,minecraft:grass)
B(8,0,5,minecraft:dirt)
B(8,1,5,minecraft:grass_block)
B(8,0,6,minecraft:grass_block)
B(8,0,7,minecraft:water)
B(8,0,8,minecraft:water)

#######################################################################
# +-----------------------------------------------------------------+ #
# |                            BO3 checks                           | #
# +-----------------------------------------------------------------+ #
#######################################################################


#######################################################################
# +-----------------------------------------------------------------+ #
# |                             Branches                            | #
# +-----------------------------------------------------------------+ #
#######################################################################


#######################################################################
# +-----------------------------------------------------------------+ #
# |                             Entities                            | #
# +-----------------------------------------------------------------+ #
#######################################################################

