
#######################################################################
# +-----------------------------------------------------------------+ #
# |                            BO3 object                           | #
# +-----------------------------------------------------------------+ #
#######################################################################

Author: Unknown

Description: No description given

Version: 3

SettingsMode: WriteWithoutComments


#######################################################################
# +-----------------------------------------------------------------+ #
# |                          Main settings                          | #
# +-----------------------------------------------------------------+ #
#######################################################################

Tree: true

Frequency: 0

Rarity: 100.0

MaxSpawn: 0

RotateRandomly: false

SpawnHeight: highestBlock

SpawnHeightOffset: 0

SpawnHeightVariance: 0

##############################
# Height Limits for the BO3. #
##############################

MinHeight: 0

MaxHeight: 256

######################
# Extrusion settings #
######################

ExtrudeMode: None

ExtrudeThroughBlocks: minecraft:air

MaxBranchDepth: 10


#######################################################################
# +-----------------------------------------------------------------+ #
# |                      Source block settings                      | #
# +-----------------------------------------------------------------+ #
#######################################################################

SourceBlocks: minecraft:air

MaxPercentageOutsideSourceBlock: 100

OutsideSourceBlock: placeAnyway

DoReplaceBlocks: true

IsOTGPlus: false


#######################################################################
# +-----------------------------------------------------------------+ #
# |                              Blocks                             | #
# +-----------------------------------------------------------------+ #
#######################################################################

B(-3,3,0,create:shadow_steel_casing)
B(-3,4,0,create:shadow_steel_casing)
B(-3,5,0,create:shadow_steel_casing)
B(-2,3,-1,create:shadow_steel_casing)
B(-2,4,-1,create:shadow_steel_casing)
B(-2,5,-1,create:shadow_steel_casing)
B(-2,2,0,create:shadow_steel_casing)
B(-2,3,0,create:shadow_steel_casing)
B(-2,4,0,create:shadow_steel_casing)
B(-2,5,0,create:shadow_steel_casing)
B(-2,3,1,create:shadow_steel_casing)
B(-2,4,1,create:shadow_steel_casing)
B(-2,5,1,create:shadow_steel_casing)
B(-1,3,-2,create:shadow_steel_casing)
B(-1,4,-2,create:shadow_steel_casing)
B(-1,5,-2,create:shadow_steel_casing)
B(-1,2,-1,create:shadow_steel_casing)
B(-1,3,-1,create:shadow_steel_casing)
B(-1,4,-1,create:shadow_steel_casing)
B(-1,5,-1,create:shadow_steel_casing)
B(-1,1,0,create:shadow_steel_casing)
B(-1,2,0,create:shadow_steel_casing)
B(-1,3,0,create:shadow_steel_casing)
B(-1,4,0,create:shadow_steel_casing)
B(-1,5,0,create:shadow_steel_casing)
B(-1,2,1,create:shadow_steel_casing)
B(-1,3,1,create:shadow_steel_casing)
B(-1,4,1,create:shadow_steel_casing)
B(-1,5,1,create:shadow_steel_casing)
B(-1,3,2,create:shadow_steel_casing)
B(-1,4,2,create:shadow_steel_casing)
B(-1,5,2,create:shadow_steel_casing)
B(0,3,-3,create:shadow_steel_casing)
B(0,4,-3,create:shadow_steel_casing)
B(0,5,-3,create:shadow_steel_casing)
B(0,2,-2,create:shadow_steel_casing)
B(0,3,-2,create:shadow_steel_casing)
B(0,4,-2,create:shadow_steel_casing)
B(0,5,-2,create:shadow_steel_casing)
B(0,1,-1,create:shadow_steel_casing)
B(0,2,-1,create:shadow_steel_casing)
B(0,3,-1,create:shadow_steel_casing)
B(0,4,-1,create:shadow_steel_casing)
B(0,5,-1,create:shadow_steel_casing)
B(0,0,0,create:shadow_steel_casing)
B(0,1,0,create:shadow_steel_casing)
B(0,2,0,create:shadow_steel_casing)
B(0,3,0,custommachinery:custom_machine_block[facing=east],test1/custommachinery_custom_machine_tile_0_3_0.nbt)
B(0,4,0,appliedenergistics2:dense_energy_cell,test1/appliedenergistics2_dense_energy_cell_0_4_0.nbt)
B(0,5,0,appliedenergistics2:controller,test1/appliedenergistics2_controller_0_5_0.nbt)
B(0,6,0,extendedcrafting:the_ultimate_block)
B(0,7,0,extendedcrafting:the_ultimate_block)
B(0,8,0,extendedcrafting:the_ultimate_block)
B(0,9,0,extendedcrafting:the_ultimate_block)
B(0,1,1,create:shadow_steel_casing)
B(0,2,1,create:shadow_steel_casing)
B(0,4,1,create:shadow_steel_casing)
B(0,5,1,create:shadow_steel_casing)
B(0,2,2,create:shadow_steel_casing)
B(0,3,2,create:shadow_steel_casing)
B(0,4,2,create:shadow_steel_casing)
B(0,5,2,create:shadow_steel_casing)
B(0,3,3,create:shadow_steel_casing)
B(0,4,3,create:shadow_steel_casing)
B(0,5,3,create:shadow_steel_casing)
B(1,3,-2,create:shadow_steel_casing)
B(1,4,-2,create:shadow_steel_casing)
B(1,5,-2,create:shadow_steel_casing)
B(1,2,-1,create:shadow_steel_casing)
B(1,3,-1,create:shadow_steel_casing)
B(1,4,-1,create:shadow_steel_casing)
B(1,5,-1,create:shadow_steel_casing)
B(1,1,0,create:shadow_steel_casing)
B(1,2,0,create:shadow_steel_casing)
B(1,3,0,create:shadow_steel_casing)
B(1,4,0,create:shadow_steel_casing)
B(1,5,0,create:shadow_steel_casing)
B(1,2,1,create:shadow_steel_casing)
B(1,3,1,create:shadow_steel_casing)
B(1,4,1,create:shadow_steel_casing)
B(1,5,1,create:shadow_steel_casing)
B(1,3,2,create:shadow_steel_casing)
B(1,4,2,create:shadow_steel_casing)
B(1,5,2,create:shadow_steel_casing)
B(2,3,-1,create:shadow_steel_casing)
B(2,4,-1,create:shadow_steel_casing)
B(2,5,-1,create:shadow_steel_casing)
B(2,2,0,create:shadow_steel_casing)
B(2,3,0,create:shadow_steel_casing)
B(2,4,0,create:shadow_steel_casing)
B(2,5,0,create:shadow_steel_casing)
B(2,3,1,create:shadow_steel_casing)
B(2,4,1,create:shadow_steel_casing)
B(2,5,1,create:shadow_steel_casing)
B(3,3,0,create:shadow_steel_casing)
B(3,4,0,create:shadow_steel_casing)
B(3,5,0,create:shadow_steel_casing)
B(3,6,0,pneumaticcraft:reinforced_chest[facing=west],test1/pneumaticcraft_reinforced_chest_3_6_0.nbt)

#######################################################################
# +-----------------------------------------------------------------+ #
# |                            BO3 checks                           | #
# +-----------------------------------------------------------------+ #
#######################################################################


#######################################################################
# +-----------------------------------------------------------------+ #
# |                             Branches                            | #
# +-----------------------------------------------------------------+ #
#######################################################################


#######################################################################
# +-----------------------------------------------------------------+ #
# |                             Entities                            | #
# +-----------------------------------------------------------------+ #
#######################################################################

