
#######################################################################
# +-----------------------------------------------------------------+ #
# |                            BO3 object                           | #
# +-----------------------------------------------------------------+ #
#######################################################################

Author: Unknown

Description: No description given

Version: 3

SettingsMode: WriteWithoutComments


#######################################################################
# +-----------------------------------------------------------------+ #
# |                          Main settings                          | #
# +-----------------------------------------------------------------+ #
#######################################################################

Tree: true

Frequency: 0

Rarity: 100.0

MaxSpawn: 0

RotateRandomly: false

SpawnHeight: highestBlock

SpawnHeightOffset: 0

SpawnHeightVariance: 0

##############################
# Height Limits for the BO3. #
##############################

MinHeight: 0

MaxHeight: 256

######################
# Extrusion settings #
######################

ExtrudeMode: None

ExtrudeThroughBlocks: minecraft:air

MaxBranchDepth: 10


#######################################################################
# +-----------------------------------------------------------------+ #
# |                      Source block settings                      | #
# +-----------------------------------------------------------------+ #
#######################################################################

SourceBlocks: minecraft:air

MaxPercentageOutsideSourceBlock: 100

OutsideSourceBlock: placeAnyway

DoReplaceBlocks: true

IsOTGPlus: false


#######################################################################
# +-----------------------------------------------------------------+ #
# |                              Blocks                             | #
# +-----------------------------------------------------------------+ #
#######################################################################

B(-4,6,-1,factoriores:lead_ore,worldspawn5/factoriores_ore_deposit_tile_-4_6_-1.nbt)
B(-4,7,-1,factoriores:lead_ore,worldspawn5/factoriores_ore_deposit_tile_-4_7_-1.nbt)
B(-4,8,-1,factoriores:lead_ore,worldspawn5/factoriores_ore_deposit_tile_-4_8_-1.nbt)
B(-4,8,0,factoriores:lead_ore,worldspawn5/factoriores_ore_deposit_tile_-4_8_0.nbt)
B(-3,8,-2,factoriores:lead_ore,worldspawn5/factoriores_ore_deposit_tile_-3_8_-2.nbt)
B(-3,5,-1,factoriores:lead_ore,worldspawn5/factoriores_ore_deposit_tile_-3_5_-1.nbt)
B(-3,6,-1,factoriores:lead_ore,worldspawn5/factoriores_ore_deposit_tile_-3_6_-1.nbt)
B(-3,7,-1,factoriores:lead_ore,worldspawn5/factoriores_ore_deposit_tile_-3_7_-1.nbt)
B(-3,8,-1,factoriores:lead_ore,worldspawn5/factoriores_ore_deposit_tile_-3_8_-1.nbt)
B(-3,6,0,factoriores:lead_ore,worldspawn5/factoriores_ore_deposit_tile_-3_6_0.nbt)
B(-3,7,0,factoriores:lead_ore,worldspawn5/factoriores_ore_deposit_tile_-3_7_0.nbt)
B(-3,8,0,factoriores:lead_ore,worldspawn5/factoriores_ore_deposit_tile_-3_8_0.nbt)
B(-3,6,1,create:shadow_steel_casing)
B(-3,7,1,create:shadow_steel_casing)
B(-3,8,1,create:shadow_steel_casing)
B(-2,7,-2,factoriores:lead_ore,worldspawn5/factoriores_ore_deposit_tile_-2_7_-2.nbt)
B(-2,7,-1,factoriores:lead_ore,worldspawn5/factoriores_ore_deposit_tile_-2_7_-1.nbt)
B(-2,8,-1,factoriores:lead_ore,worldspawn5/factoriores_ore_deposit_tile_-2_8_-1.nbt)
B(-2,6,0,create:shadow_steel_casing)
B(-2,7,0,create:shadow_steel_casing)
B(-2,8,0,create:shadow_steel_casing)
B(-2,5,1,create:shadow_steel_casing)
B(-2,6,1,create:shadow_steel_casing)
B(-2,7,1,create:shadow_steel_casing)
B(-2,8,1,create:shadow_steel_casing)
B(-2,6,2,create:shadow_steel_casing)
B(-2,7,2,create:shadow_steel_casing)
B(-2,8,2,create:shadow_steel_casing)
B(-2,7,3,factoriores:copper_ore,worldspawn5/factoriores_ore_deposit_tile_-2_7_3.nbt)
B(-2,7,4,factoriores:copper_ore,worldspawn5/factoriores_ore_deposit_tile_-2_7_4.nbt)
B(-2,8,4,factoriores:copper_ore,worldspawn5/factoriores_ore_deposit_tile_-2_8_4.nbt)
B(-1,6,-1,create:shadow_steel_casing)
B(-1,7,-1,create:shadow_steel_casing)
B(-1,8,-1,create:shadow_steel_casing)
B(-1,5,0,create:shadow_steel_casing)
B(-1,6,0,create:shadow_steel_casing)
B(-1,7,0,create:shadow_steel_casing)
B(-1,8,0,create:shadow_steel_casing)
B(-1,4,1,create:shadow_steel_casing)
B(-1,5,1,create:shadow_steel_casing)
B(-1,6,1,custommachinery:custom_machine_block[facing=west],worldspawn5/custommachinery_custom_machine_tile_-1_6_1.nbt)
B(-1,7,1,create:shadow_steel_casing)
B(-1,8,1,create:shadow_steel_casing)
B(-1,5,2,create:shadow_steel_casing)
B(-1,6,2,create:shadow_steel_casing)
B(-1,7,2,create:shadow_steel_casing)
B(-1,8,2,create:shadow_steel_casing)
B(-1,6,3,create:shadow_steel_casing)
B(-1,7,3,create:shadow_steel_casing)
B(-1,8,3,create:shadow_steel_casing)
B(0,6,-2,create:shadow_steel_casing)
B(0,7,-2,create:shadow_steel_casing)
B(0,8,-2,create:shadow_steel_casing)
B(0,5,-1,create:shadow_steel_casing)
B(0,6,-1,create:shadow_steel_casing)
B(0,7,-1,create:shadow_steel_casing)
B(0,8,-1,create:shadow_steel_casing)
B(0,4,0,create:shadow_steel_casing)
B(0,5,0,create:shadow_steel_casing)
B(0,6,0,custommachinery:custom_machine_block,worldspawn5/custommachinery_custom_machine_tile_0_6_0.nbt)
B(0,7,0,create:shadow_steel_casing)
B(0,8,0,create:shadow_steel_casing)
B(0,9,0,appliedenergistics2:smooth_sky_stone_chest,worldspawn5/appliedenergistics2_sky_chest_0_9_0.nbt)
B(0,3,1,create:shadow_steel_casing)
B(0,4,1,create:shadow_steel_casing)
B(0,5,1,create:shadow_steel_casing)
B(0,6,1,custommachinery:custom_machine_block[facing=south],worldspawn5/custommachinery_custom_machine_tile_0_6_1.nbt)
B(0,7,1,appliedenergistics2:dense_energy_cell,worldspawn5/appliedenergistics2_dense_energy_cell_0_7_1.nbt)
B(0,8,1,appliedenergistics2:controller,worldspawn5/appliedenergistics2_controller_0_8_1.nbt)
B(0,9,1,extendedcrafting:the_ultimate_block)
B(0,10,1,extendedcrafting:the_ultimate_block)
B(0,11,1,extendedcrafting:the_ultimate_block)
B(0,12,1,extendedcrafting:the_ultimate_block)
B(0,4,2,create:shadow_steel_casing)
B(0,5,2,create:shadow_steel_casing)
B(0,6,2,custommachinery:custom_machine_block[facing=south],worldspawn5/custommachinery_custom_machine_tile_0_6_2.nbt)
B(0,7,2,create:shadow_steel_casing)
B(0,8,2,create:shadow_steel_casing)
B(0,5,3,create:shadow_steel_casing)
B(0,6,3,create:shadow_steel_casing)
B(0,7,3,create:shadow_steel_casing)
B(0,8,3,create:shadow_steel_casing)
B(0,6,4,create:shadow_steel_casing)
B(0,7,4,create:shadow_steel_casing)
B(0,8,4,create:shadow_steel_casing)
B(1,6,-1,create:shadow_steel_casing)
B(1,7,-1,create:shadow_steel_casing)
B(1,8,-1,create:shadow_steel_casing)
B(1,5,0,create:shadow_steel_casing)
B(1,6,0,create:shadow_steel_casing)
B(1,7,0,create:shadow_steel_casing)
B(1,8,0,create:shadow_steel_casing)
B(1,4,1,create:shadow_steel_casing)
B(1,5,1,create:shadow_steel_casing)
B(1,6,1,custommachinery:custom_machine_block[facing=east],worldspawn5/custommachinery_custom_machine_tile_1_6_1.nbt)
B(1,7,1,create:shadow_steel_casing)
B(1,8,1,create:shadow_steel_casing)
B(1,5,2,create:shadow_steel_casing)
B(1,6,2,create:shadow_steel_casing)
B(1,7,2,create:shadow_steel_casing)
B(1,8,2,create:shadow_steel_casing)
B(1,6,3,create:shadow_steel_casing)
B(1,7,3,create:shadow_steel_casing)
B(1,8,3,create:shadow_steel_casing)
B(2,6,0,create:shadow_steel_casing)
B(2,7,0,create:shadow_steel_casing)
B(2,8,0,create:shadow_steel_casing)
B(2,5,1,create:shadow_steel_casing)
B(2,6,1,create:shadow_steel_casing)
B(2,7,1,create:shadow_steel_casing)
B(2,8,1,create:shadow_steel_casing)
B(2,6,2,create:shadow_steel_casing)
B(2,7,2,create:shadow_steel_casing)
B(2,8,2,create:shadow_steel_casing)
B(2,7,3,factoriores:iron_ore,worldspawn5/factoriores_ore_deposit_tile_2_7_3.nbt)
B(2,8,3,factoriores:iron_ore,worldspawn5/factoriores_ore_deposit_tile_2_8_3.nbt)
B(3,6,1,create:shadow_steel_casing)
B(3,7,1,create:shadow_steel_casing)
B(3,8,1,create:shadow_steel_casing)
B(3,7,2,factoriores:iron_ore,worldspawn5/factoriores_ore_deposit_tile_3_7_2.nbt)
B(3,8,2,factoriores:iron_ore,worldspawn5/factoriores_ore_deposit_tile_3_8_2.nbt)
B(3,5,3,factoriores:iron_ore,worldspawn5/factoriores_ore_deposit_tile_3_5_3.nbt)
B(3,6,3,factoriores:iron_ore,worldspawn5/factoriores_ore_deposit_tile_3_6_3.nbt)
B(3,7,3,factoriores:iron_ore,worldspawn5/factoriores_ore_deposit_tile_3_7_3.nbt)
B(3,8,3,factoriores:iron_ore,worldspawn5/factoriores_ore_deposit_tile_3_8_3.nbt)
B(4,6,1,factoriores:iron_ore,worldspawn5/factoriores_ore_deposit_tile_4_6_1.nbt)
B(4,7,1,factoriores:iron_ore,worldspawn5/factoriores_ore_deposit_tile_4_7_1.nbt)
B(4,8,1,factoriores:iron_ore,worldspawn5/factoriores_ore_deposit_tile_4_8_1.nbt)
B(4,5,2,factoriores:iron_ore,worldspawn5/factoriores_ore_deposit_tile_4_5_2.nbt)
B(4,6,2,factoriores:iron_ore,worldspawn5/factoriores_ore_deposit_tile_4_6_2.nbt)
B(4,7,2,factoriores:iron_ore,worldspawn5/factoriores_ore_deposit_tile_4_7_2.nbt)
B(4,8,2,factoriores:iron_ore,worldspawn5/factoriores_ore_deposit_tile_4_8_2.nbt)
B(4,6,3,factoriores:iron_ore,worldspawn5/factoriores_ore_deposit_tile_4_6_3.nbt)
B(4,7,3,factoriores:iron_ore,worldspawn5/factoriores_ore_deposit_tile_4_7_3.nbt)
B(5,7,2,factoriores:iron_ore,worldspawn5/factoriores_ore_deposit_tile_5_7_2.nbt)
B(5,8,2,factoriores:iron_ore,worldspawn5/factoriores_ore_deposit_tile_5_8_2.nbt)

#######################################################################
# +-----------------------------------------------------------------+ #
# |                            BO3 checks                           | #
# +-----------------------------------------------------------------+ #
#######################################################################


#######################################################################
# +-----------------------------------------------------------------+ #
# |                             Branches                            | #
# +-----------------------------------------------------------------+ #
#######################################################################


#######################################################################
# +-----------------------------------------------------------------+ #
# |                             Entities                            | #
# +-----------------------------------------------------------------+ #
#######################################################################

