
#######################################################################
# +-----------------------------------------------------------------+ #
# |                            BO3 object                           | #
# +-----------------------------------------------------------------+ #
#######################################################################

Author: Unknown

Description: No description given

Version: 3

SettingsMode: WriteWithoutComments


#######################################################################
# +-----------------------------------------------------------------+ #
# |                          Main settings                          | #
# +-----------------------------------------------------------------+ #
#######################################################################

Tree: true

Frequency: 0

Rarity: 100.0

MaxSpawn: 0

RotateRandomly: false

SpawnHeight: highestBlock

SpawnHeightOffset: 0

SpawnHeightVariance: 0

##############################
# Height Limits for the BO3. #
##############################

MinHeight: 0

MaxHeight: 256

######################
# Extrusion settings #
######################

ExtrudeMode: None

ExtrudeThroughBlocks: minecraft:air

MaxBranchDepth: 10


#######################################################################
# +-----------------------------------------------------------------+ #
# |                      Source block settings                      | #
# +-----------------------------------------------------------------+ #
#######################################################################

SourceBlocks: minecraft:air

MaxPercentageOutsideSourceBlock: 100

OutsideSourceBlock: placeAnyway

DoReplaceBlocks: true

IsOTGPlus: false


#######################################################################
# +-----------------------------------------------------------------+ #
# |                              Blocks                             | #
# +-----------------------------------------------------------------+ #
#######################################################################

B(-3,6,0,create:shadow_steel_casing)
B(-3,7,0,create:shadow_steel_casing)
B(-3,8,0,create:shadow_steel_casing)
B(-2,6,-1,create:shadow_steel_casing)
B(-2,7,-1,create:shadow_steel_casing)
B(-2,8,-1,create:shadow_steel_casing)
B(-2,5,0,create:shadow_steel_casing)
B(-2,6,0,create:shadow_steel_casing)
B(-2,7,0,create:shadow_steel_casing)
B(-2,8,0,create:shadow_steel_casing)
B(-2,6,1,create:shadow_steel_casing)
B(-2,7,1,create:shadow_steel_casing)
B(-2,8,1,create:shadow_steel_casing)
B(-1,6,-2,create:shadow_steel_casing)
B(-1,7,-2,create:shadow_steel_casing)
B(-1,8,-2,create:shadow_steel_casing)
B(-1,5,-1,create:shadow_steel_casing)
B(-1,6,-1,create:shadow_steel_casing)
B(-1,7,-1,create:shadow_steel_casing)
B(-1,8,-1,create:shadow_steel_casing)
B(-1,4,0,create:shadow_steel_casing)
B(-1,5,0,create:shadow_steel_casing)
B(-1,6,0,create:shadow_steel_casing)
B(-1,7,0,create:shadow_steel_casing)
B(-1,8,0,create:shadow_steel_casing)
B(-1,5,1,create:shadow_steel_casing)
B(-1,6,1,create:shadow_steel_casing)
B(-1,7,1,create:shadow_steel_casing)
B(-1,8,1,create:shadow_steel_casing)
B(-1,6,2,create:shadow_steel_casing)
B(-1,7,2,create:shadow_steel_casing)
B(-1,8,2,create:shadow_steel_casing)
B(0,6,-3,create:shadow_steel_casing)
B(0,7,-3,create:shadow_steel_casing)
B(0,8,-3,create:shadow_steel_casing)
B(0,5,-2,create:shadow_steel_casing)
B(0,6,-2,create:shadow_steel_casing)
B(0,7,-2,create:shadow_steel_casing)
B(0,8,-2,create:shadow_steel_casing)
B(0,4,-1,create:shadow_steel_casing)
B(0,5,-1,create:shadow_steel_casing)
B(0,6,-1,create:shadow_steel_casing)
B(0,7,-1,create:shadow_steel_casing)
B(0,8,-1,create:shadow_steel_casing)
B(0,3,0,create:shadow_steel_casing)
B(0,4,0,create:shadow_steel_casing)
B(0,5,0,create:shadow_steel_casing)
B(0,6,0,custommachinery:custom_machine_block[facing=east],worldspawn1/custommachinery_custom_machine_tile_0_6_0.nbt)
B(0,7,0,appliedenergistics2:dense_energy_cell,worldspawn1/appliedenergistics2_dense_energy_cell_0_7_0.nbt)
B(0,8,0,appliedenergistics2:controller,worldspawn1/appliedenergistics2_controller_0_8_0.nbt)
B(0,9,0,extendedcrafting:the_ultimate_block)
B(0,10,0,extendedcrafting:the_ultimate_block)
B(0,11,0,extendedcrafting:the_ultimate_block)
B(0,12,0,extendedcrafting:the_ultimate_block)
B(0,4,1,create:shadow_steel_casing)
B(0,5,1,create:shadow_steel_casing)
B(0,7,1,create:shadow_steel_casing)
B(0,8,1,create:shadow_steel_casing)
B(0,5,2,create:shadow_steel_casing)
B(0,6,2,create:shadow_steel_casing)
B(0,7,2,create:shadow_steel_casing)
B(0,8,2,create:shadow_steel_casing)
B(0,6,3,create:shadow_steel_casing)
B(0,7,3,create:shadow_steel_casing)
B(0,8,3,create:shadow_steel_casing)
B(1,6,-2,create:shadow_steel_casing)
B(1,7,-2,create:shadow_steel_casing)
B(1,8,-2,create:shadow_steel_casing)
B(1,5,-1,create:shadow_steel_casing)
B(1,6,-1,create:shadow_steel_casing)
B(1,7,-1,create:shadow_steel_casing)
B(1,8,-1,create:shadow_steel_casing)
B(1,4,0,create:shadow_steel_casing)
B(1,5,0,create:shadow_steel_casing)
B(1,6,0,create:shadow_steel_casing)
B(1,7,0,create:shadow_steel_casing)
B(1,8,0,create:shadow_steel_casing)
B(1,5,1,create:shadow_steel_casing)
B(1,6,1,create:shadow_steel_casing)
B(1,7,1,create:shadow_steel_casing)
B(1,8,1,create:shadow_steel_casing)
B(1,6,2,create:shadow_steel_casing)
B(1,7,2,create:shadow_steel_casing)
B(1,8,2,create:shadow_steel_casing)
B(2,6,-1,create:shadow_steel_casing)
B(2,7,-1,create:shadow_steel_casing)
B(2,8,-1,create:shadow_steel_casing)
B(2,5,0,create:shadow_steel_casing)
B(2,6,0,create:shadow_steel_casing)
B(2,7,0,create:shadow_steel_casing)
B(2,8,0,create:shadow_steel_casing)
B(2,6,1,create:shadow_steel_casing)
B(2,7,1,create:shadow_steel_casing)
B(2,8,1,create:shadow_steel_casing)
B(3,6,0,create:shadow_steel_casing)
B(3,7,0,create:shadow_steel_casing)
B(3,8,0,create:shadow_steel_casing)
B(3,9,0,pneumaticcraft:reinforced_chest[facing=west],worldspawn1/pneumaticcraft_reinforced_chest_3_9_0.nbt)

#######################################################################
# +-----------------------------------------------------------------+ #
# |                            BO3 checks                           | #
# +-----------------------------------------------------------------+ #
#######################################################################


#######################################################################
# +-----------------------------------------------------------------+ #
# |                             Branches                            | #
# +-----------------------------------------------------------------+ #
#######################################################################


#######################################################################
# +-----------------------------------------------------------------+ #
# |                             Entities                            | #
# +-----------------------------------------------------------------+ #
#######################################################################

